Workbook

Sheet CONFINAMENTO-MILHO
A1: IRRIGAÇÃP SETOR 1 | D1: ADUBO | H1: APURAÇÃO | M1: MAQUINARIO-ADUBAÇÃO-PLANTIO--CAPINA | S1: VENENO
A2: DATA | B2: MINUTOS | D2: DESCRIÇÃO | E2: DATA | F2: QUANT | H2: DESCRIÇÃO | I2: TOTAL | J2: VALOR COMPRA | K2: CUSTO USADO | M2: DESCRIÇÃO | N2: DATA | O2: QUANT | P2: VALOR | Q2: TOTAL | S2: DESCRIÇÃO | T2: DATA | U2: QUANT | V2: VALOR | W2: TOTAL
A3: 45643 | B3: 160 | D3: SEMENTE DE MILHO BIOMATRIX 3066 | E3: 45527 | F3: 8 | H3: ABADIN 72 EC - 1 LITRO | I3: =SUMIF('CONFINAMENTO-MILHO'!D3:D243,"ABADIN 72 EC - 1 LITRO",'CONFINAMENTO-MILHO'!F3:F243) -> 0 | J3: =COMPRAS!M3 -> 0.13 | K3: =I3*J3 -> 0 | M3: DIARIA MAIKO | N3: 45654 | O3: 1 | P3: 75 | Q3: =O3*P3 -> 75 | S3: LUIZ | T3: 45654 | U3: 4 | V3: 10 | W3: =U3*V3 -> 40
A4: 45644 | B4: 190 | D4: ROUNDUP ORIGINAL MAIS - GL DE 5 L | E4: 45654 | F4: 800 | H4: ABAMEX -1 LITRO | I4: =SUMIF('CONFINAMENTO-MILHO'!D3:D244,"ABAMEX -1 LITRO",'CONFINAMENTO-MILHO'!F3:F244) -> 0 | J4: =COMPRAS!M4 -> 0.05 | K4: =I4*J4 -> 0 | M4: GRADEAÇÃO | O4: 1 | P4: 231 | Q4: =O4*P4 -> 231 | S4: LUIZ | T4: 45660 | U4: 4 | V4: 10 | W4: =U4*V4 -> 40
A5: 45645 | B5: 200 | D5: BRIT | E5: 45654 | F5: 80 | H5: ABAMEX MAXX 72% 12X1 LT | I5: =SUMIF('CONFINAMENTO-MILHO'!D3:D244,"ABAMEX MAXX 72% 12X1 LT",'CONFINAMENTO-MILHO'!F3:F244) -> 0 | J5: =COMPRAS!M5 -> 0.1 | K5: =I5*J5 -> 0 | M5: PLANTIO E REPLANTIO | O5: 3 | P5: 80 | Q5: =U5*P5 -> 320 | S5: LUIZ | T5: 45664 | U5: 4 | V5: 10 | W5: =U5*V5 -> 40
A6: 45646 | B6: 200 | D6: UREIA | E6: 45659 | F6: 72 | H6: ACIDO BORICO SACO 25K | I6: =SUMIF('CONFINAMENTO-MILHO'!D3:D222,"ACIDO BORICO SECO 25K ",'CONFINAMENTO-MILHO'!F3:F222) -> 0 | J6: =COMPRAS!M6 -> 10.2 | K6: =I6*J6 -> 0 | M6: MONTAGEM SISTEMA | O6: 1 | P6: 80 | Q6: =O6*P6 -> 80 | R6: LUIZ | S6: LUIZ | T6: 45675 | U6: 4 | V6: 10 | W6: =U6*V6 -> 40
A7: 45647 | B7: 220 | D7: PIRATE 1 LITRO | E7: 45660 | F7: 160 | H7: ADESIL - 1 LITRO | I7: =SUMIF('CONFINAMENTO-MILHO'!D3:D222,"ADESIL - 1 LITRO ",'CONFINAMENTO-MILHO'!F3:F222) -> 0 | J7: =COMPRAS!M7 -> 0.025 | K7: =I7*J7 -> 0 | M7: ETIRADA MANGUIERAS | O7: 1 | P7: 80 | Q7: =O7*P7 -> 80 | S7: LUIZ | T7: 45678 | U7: 6 | V7: 10 | W7: =U7*V7 -> 60
A8: 45648 | B8: 200 | D8: BRIT | E8: 45660 | F8: 80 | H8: AGRUMAX MZ 4X5 KG | I8: =SUMIF('CONFINAMENTO-MILHO'!D3:D222,"AGRUMAX MZ 4X5 KG ",'CONFINAMENTO-MILHO'!F3:F222) -> 0 | J8: =COMPRAS!M8 -> 0.032 | K8: =I8*J8 -> 0 | M8: NIVELAMENTO NUNAO | O8: 1 | P8: 240 | Q8: =O8*P8 -> 240 | S8: LUIZ | T8: 45693 | U8: 2 | V8: 10 | W8: =U8*V8 -> 20
A9: 45649 | B9: 210 | D9: INTREPID240 SC -1 L | E9: 45660 | F9: 120 | H9: AMISTAR TOP 1 L | I9: =SUMIF('CONFINAMENTO-MILHO'!D3:D223,"AMISTAR TOP 1 L",'CONFINAMENTO-MILHO'!F3:F223) -> 0 | J9: =COMPRAS!M9 -> 0.205 | K9: =I9*J9 -> 0 | M9: CUSTO FEITA | O9: 1 | P9: 1050 | Q9: =O9*P9 -> 1050
A10: 45650 | B10: 160 | D10: QUIMIFOL S450 - GL 5 LITROS | E10: 45660 | F10: 120 | H10: AMISTAR WG 6X500 G-1 KILO | I10: =SUMIF('CONFINAMENTO-MILHO'!D3:D223,"AMISTAR WG 6X500 G-1 KILO",'CONFINAMENTO-MILHO'!F3:F223) -> 0 | J10: =COMPRAS!M10 -> 0.2 | K10: =I10*J10 -> 0 | M10: CUSTO SACO | O10: 672 | P10: 1.35 | Q10: =O10*P10 -> 907.2
A11: 45651 | D11: LANNATE | E11: 45664 | F11: 400 | H11: AMPLIGO 250 ML | I11: =SUMIF('CONFINAMENTO-MILHO'!D3:D223,"AMPLIGO 250 ML",'CONFINAMENTO-MILHO'!F3:F223) -> 0 | J11: =COMPRAS!M11 -> 0.39 | K11: =I11*J11 -> 0 | M11: DIARIAS ENSACAR | O11: 14 | P11: 80 | Q11: =O11*P11 -> 1120
A12: 45652 | B12: 180 | D12: INTREPID240 SC -1 L | E12: 45664 | F12: 120 | H12: AVATAR 1 L | I12: =SUMIF('CONFINAMENTO-MILHO'!D3:D243,"AVATAR 1 L",'CONFINAMENTO-MILHO'!F3:F243) -> 0 | J12: =COMPRAS!M12 -> 0.375 | K12: =I12*J12 -> 0 | Q12: =O12*P12 -> 0
A13: 45653 | B13: 180 | D13: RAPEL PCT- 3 KG | E13: 45664 | F13: 480 | H13: BARBANTE EM NOVELO N10 BRANCO | I13: =SUMIF('CONFINAMENTO-MILHO'!D3:D230,"BARBANTE EM NOVELO N10 BRANCO",'CONFINAMENTO-MILHO'!F3:F230) -> 0 | J13: =COMPRAS!M13 -> 29.625 | K13: =I13*J13 -> 0 | Q13: =O13*P13 -> 0
A14: 45654 | B14: 180 | D14: LANNATE | E14: 45675 | F14: 400 | H14: BARBANTE EM NOVELO N8 OURO | I14: =SUMIF('CONFINAMENTO-MILHO'!D3:D229,"BARBANTE EM NOVELO N8 OURO",'CONFINAMENTO-MILHO'!F3:F229) -> 0 | J14: =COMPRAS!M14 -> 31.576923 | K14: =I14*J14 -> 0 | Q14: =O14*P14 -> 0
A15: 45655 | B15: 160 | D15: INTREPID240 SC -1 L | E15: 45675 | F15: 120 | H15: BENZOATO 1K | I15: =SUMIF('CONFINAMENTO-MILHO'!D3:D243,"BENZOATO 1K",'CONFINAMENTO-MILHO'!F3:F243) -> 0 | J15: =COMPRAS!M15 -> 0.45 | K15: =I15*J15 -> 0 | Q15: =O15*P15 -> 0
A16: 45656 | B16: 170 | D16: QUIMIFOL S450 - GL 5 LITROS | E16: 45675 | F16: 240 | H16: BION 500 WG 25 G | I16: =SUMIF('CONFINAMENTO-MILHO'!D3:D222,"BION 500 WG 25 G",'CONFINAMENTO-MILHO'!F3:F222) -> 0 | J16: =COMPRAS!M16 -> 2.8 | K16: =I16*J16 -> 0 | Q16: =O16*P16 -> 0
A17: 45657 | D17: ROUNDUP ORIGINAL MAIS - GL DE 5 L | E17: 45676 | F17: 1500 | H17: BRAVONIL ULTREX 1 KILO | I17: =SUMIF('CONFINAMENTO-MILHO'!D3:D222,"BRAVONIL ULTREX 1 KILO",'CONFINAMENTO-MILHO'!F3:F222) -> 0 | J17: =COMPRAS!M17 -> 0.1 | K17: =I17*J17 -> 0 | Q17: =O17*P17 -> 0
A18: 45658 | D18: UREIA | E18: 45678 | F18: 40 | H18: BRIT | I18: =SUMIF('CONFINAMENTO-MILHO'!D3:D242,"BRIT",'CONFINAMENTO-MILHO'!F3:F242) -> 160 | J18: =COMPRAS!M18 -> 0.065 | K18: =I18*J18 -> 10.4 | Q18: =O18*P18 -> 0
A19: 45659 | D19: SUFATO DE AMONIO | E19: 45678 | F19: 40 | H19: CAIXA PARA TOMATE | I19: =SUMIF('CONFINAMENTO-MILHO'!D3:D222,"CAIXA PARA TOMATE ",'CONFINAMENTO-MILHO'!F3:F222) -> 0 | J19: =COMPRAS!M19 -> 0 | K19: =I19*J19 -> 0 | Q19: =O19*P19 -> 0
A20: 45660 | B20: 80 | D20: NITRATO POTASSIO YARA TERA K 13-00-43 | E20: 45678 | F20: 40 | H20: CAL SUPER 5 LITROS | I20: =SUMIF('CONFINAMENTO-MILHO'!D3:D233,"CAL SUPER 5 LITROS",'CONFINAMENTO-MILHO'!F3:F233) -> 0 | J20: =COMPRAS!M20 -> 0.044 | K20: =I20*J20 -> 0 | Q20: =O20*P20 -> 0
A21: 45661 | B21: 120 | D21: INTREPID240 SC -1 L | E21: 45693 | F21: 60 | H21: CARNADINE- 1 LITRO | I21: =SUMIF('CONFINAMENTO-MILHO'!D3:D247,"CARNADINE- 1 LITRO",'CONFINAMENTO-MILHO'!F3:F247) -> 0 | J21: =COMPRAS!M21 -> 0.060833333 | K21: =I21*J21 -> 0
A22: 45662 | D22: PLATINUM NEO - GL 5 LITROS | E22: 45693 | F22: 60 | H22: CERCOBIN 875 WG- 1 KG | I22: =SUMIF('CONFINAMENTO-MILHO'!D3:D247,"CERCOBIN 875 WG- 1 KG",'CONFINAMENTO-MILHO'!F3:F247) -> 0 | J22: =COMPRAS!M22 -> 0.085 | K22: =I22*J22 -> 0
A23: 45663 | D23: NPK | E23: 45724 | F23: 104 | H23: D FIX - 1 LITRO | I23: =SUMIF('CONFINAMENTO-MILHO'!D3:D243,"D FIX - 1 LITRO",'CONFINAMENTO-MILHO'!F3:F243) -> 0 | J23: =COMPRAS!M23 -> 0.11 | K23: =I23*J23 -> 0
A24: 45664 | B24: 90 | H24: D S30 - 1 LITRO | I24: =SUMIF('CONFINAMENTO-MILHO'!D3:D243,"D S30 - 1 LITRO",'CONFINAMENTO-MILHO'!F3:F243) -> 0 | J24: =COMPRAS!M24 -> 0.065 | K24: =I24*J24 -> 0
A25: 45665 | H25: DELEGATE(TM) - FR 120 GR | I25: =SUMIF('CONFINAMENTO-MILHO'!D3:D243,"DELEGATE(TM) - FR 120 GR",'CONFINAMENTO-MILHO'!F3:F243) -> 0 | J25: =COMPRAS!M25 -> 2.75 | K25: =I25*J25 -> 0
A26: 45666 | H26: DFULL 1 LITRO | I26: =SUMIF('CONFINAMENTO-MILHO'!D3:D243,"DFULL 1 LITRO",'CONFINAMENTO-MILHO'!F3:F243) -> 0 | J26: =COMPRAS!M26 -> 0.155 | K26: =I26*J26 -> 0
A27: 45667 | H27: DICARZOL 500 SP 12 X 500 GRS | I27: =SUMIF('CONFINAMENTO-MILHO'!D3:D243,"DICARZOL 500 SP 12 X 500 GRS",'CONFINAMENTO-MILHO'!F3:F243) -> 0 | J27: =COMPRAS!M27 -> 0.76 | K27: =I27*J27 -> 0
A28: 45668 | H28: DISPAROULTRA-S - GL DE 5 LITROS | I28: =SUMIF('CONFINAMENTO-MILHO'!D3:D243,"DISPAROULTRA-S - GL DE 5 LITROS",'CONFINAMENTO-MILHO'!F3:F243) -> 0 | J28: =COMPRAS!M28 -> 0.028 | K28: =I28*J28 -> 0
A29: 45669 | H29: DOMINUM XT-S - GL 5 LITROS | I29: =SUMIF('CONFINAMENTO-MILHO'!D3:D243,"DOMINUM XT-S - GL 5 LITROS",'CONFINAMENTO-MILHO'!F3:F243) -> 0 | J29: =COMPRAS!M29 -> 0.128 | K29: =I29*J29 -> 0
A30: 45670 | H30: DRIPSOL BORO K 00.00.01+17% BORO 25 k | I30: =SUMIF('CONFINAMENTO-MILHO'!D3:D243,"DRIPSOL BORO K 00.00.01+17% BORO 25 k",'CONFINAMENTO-MILHO'!F3:F243) -> 0 | J30: =COMPRAS!M30 -> 11.4 | K30: =I30*J30 -> 0
A31: 45671 | H31: DRIPSOL CRESCIMENTO 24-10-10 25 KG | I31: =SUMIF('CONFINAMENTO-MILHO'!D3:D238,"DRIPSOL CRESCIMENTO 24-10-10 25 KG",'CONFINAMENTO-MILHO'!F3:F238) -> 0 | J31: =COMPRAS!M31 -> 10.6 | K31: =I31*J31 -> 0
A32: 45672 | H32: DRIPSOL INICIAL 15-30-15 25 KG | I32: =SUMIF('CONFINAMENTO-MILHO'!D3:D222,"DRIPSOL INICIAL 15-30-15 25 KG",'CONFINAMENTO-MILHO'!F3:F222) -> 0 | J32: =COMPRAS!M32 -> 9.2769231 | K32: =I32*J32 -> 0
A33: 45673 | H33: DRIPSOL MICRO REXENE 700 GRAMAS | I33: =SUMIF('CONFINAMENTO-MILHO'!D3:D222,"DRIPSOL MICRO REXENE 700 GRAMAS",'CONFINAMENTO-MILHO'!F3:F222) -> 0 | J33: =COMPRAS!M33 -> 0.082857143 | K33: =I33*J33 -> 0
A34: 45674 | H34: DRIPSOL MULTIPROPOSITO-18-18-18 25 K | I34: =SUMIF('CONFINAMENTO-MILHO'!D3:D222,"DRIPSOL MULTIPROPOSITO-18-18-18 25 K",'CONFINAMENTO-MILHO'!F3:F222) -> 0 | J34: =COMPRAS!M34 -> 10.56 | K34: =I34*J34 -> 0
A35: 45675 | H35: DRIPSOL PRODUÇÃO 12-06-40 25K | I35: =SUMIF('CONFINAMENTO-MILHO'!D3:D236,"DRIPSOL PRODUÇÃO 12-06-40 25K",'CONFINAMENTO-MILHO'!F3:F236) -> 0 | J35: =COMPRAS!M35 -> 11 | K35: =I35*J35 -> 0 | N35: TOTAL | O35: =SUM(O3:O34) -> 695 | Q35: =SUM(Q3:Q34) -> 4103.2 | T35: TOTAL | U35: =SUM(U3:U31) -> 24 | W35: =SUM(W3:W31) -> 240
A36: 45676 | H36: ELEITTO | I36: =SUMIF('CONFINAMENTO-MILHO'!D3:D223,"ELEITTO",'CONFINAMENTO-MILHO'!F3:F223) -> 0 | J36: =COMPRAS!M36 -> 0.33 | K36: =I36*J36 -> 0
A37: 45677 | B37: 131 | H37: FERTIUM LIQUIDO 5L | I37: =SUMIF('CONFINAMENTO-MILHO'!D3:D231,"FERTIUM LIQUIDO 5L",'CONFINAMENTO-MILHO'!F3:F231) -> 0 | J37: =COMPRAS!M37 -> 0.217 | K37: =I37*J37 -> 0
A38: 45678 | B38: 156 | H38: FITILHO VIRGEM NOVELO NR 08 | I38: =SUMIF('CONFINAMENTO-MILHO'!D3:D243,"FITILHO VIRGEM NOVELO NR 08",'CONFINAMENTO-MILHO'!F3:F243) -> 0 | J38: =COMPRAS!M38 -> 40 | K38: =I38*J38 -> 0 | M38: REEMBOLSO DE PAGAMENTO | S38: REEMBOLSO DE PAGAMENTO
A39: 45679 | B39: 155 | H39: FRETE CAIXAS TOMATE | I39: =SUMIF('CONFINAMENTO-MILHO'!D3:D243,"FRETE CAIXAS",'CONFINAMENTO-MILHO'!F3:F243) -> 0 | J39: =COMPRAS!M39 -> 2.3571429 | K39: =I39*J39 -> 0 | M39: REEMBOLSO FERNANDO | N39: =SUMIF('CONFINAMENTO-MILHO'!R1:R30,"R.FERNANDO",'CONFINAMENTO-MILHO'!Q1:Q30) -> 0 | S39: REEMBOLSO FERNANDO | T39: =SUMIF('CONFINAMENTO-MILHO'!X1:X30,"R.FERNANDO",'CONFINAMENTO-MILHO'!W1:W30) -> 0
A40: 45680 | B40: 160 | H40: FTE 25K | I40: =SUMIF('CONFINAMENTO-MILHO'!D3:D241,"FTE 50 KILOS ",'CONFINAMENTO-MILHO'!F3:F241) -> 0 | J40: =COMPRAS!M40 -> 4.4 | K40: =I40*J40 -> 0 | M40: REEMBOLSO RAFAEL | N40: =SUMIF('CONFINAMENTO-MILHO'!R1:R30,"R.RAFAEL",'CONFINAMENTO-MILHO'!Q1:Q30) -> 0 | S40: REEMBOLSO RAFAEL | T40: =SUMIF('CONFINAMENTO-MILHO'!X1:X30,"R.RAFAEL",'CONFINAMENTO-MILHO'!W1:W30) -> 0
...

Sheet TOMATE
A1: IRRIGAÇÃP SETOR 1 | D1: ADUBO | H1: APURAÇÃO | M1: MAQUINARIO-ADUBAÇÃO-PLANTIO--CAPINA | S1: VENENO
A2: DATA | B2: MINUTOS | D2: DESCRIÇÃO | E2: DATA | F2: QUANT | H2: DESCRIÇÃO | I2: TOTAL | J2: VALOR COMPRA | K2: CUSTO USADO | M2: DESCRIÇÃO | N2: DATA | O2: QUANT | P2: VALOR | Q2: TOTAL | S2: DESCRIÇÃO | T2: DATA | U2: QUANT | V2: VALOR | W2: TOTAL
D3: NUTRISYSTEM INICIAL 42 06.30.06 25 K | E3: 45630 | F3: 536.3 | H3: ABADIN 72 EC - 1 LITRO | I3: =SUMIF(TOMATE!D3:D243,"ABADIN 72 EC - 1 LITRO",TOMATE!F3:F243) -> 300 | J3: =COMPRAS!M3 -> 0.13 | K3: =I3*J3 -> 39 | M3: DIARIA RICARDO | N3: 45625 | O3: 0.5 | P3: 70 | Q3: =O3*P3 -> 35 | R3: R.FERNANDO | T3: 45636 | U3: 1.5 | V3: 10 | W3: =U3*V3 -> 15
D4: PRIMAZ | E4: 45630 | F4: 114.1 | H4: ABAMEX -1 LITRO | I4: =SUMIF(TOMATE!D3:D244,"ABAMEX -1 LITRO",TOMATE!F3:F244) -> 0 | J4: =COMPRAS!M4 -> 0.05 | K4: =I4*J4 -> 0 | M4: DIARIA AMIGO | N4: 45625 | O4: 0.5 | P4: 70 | Q4: =O4*P4 -> 35 | R4: R.FERNANDO | T4: 45643 | U4: 2 | V4: 10 | W4: =U4*V4 -> 20
D5: NUTRISYSTEM INICIAL 42 06.30.06 25 K | E5: 45630 | F5: -13.7 | H5: ABAMEX MAXX 72% 12X1 LT | I5: =SUMIF(TOMATE!D3:D244,"ABAMEX MAXX 72% 12X1 LT",TOMATE!F3:F244) -> 0 | J5: =COMPRAS!M5 -> 0.1 | K5: =I5*J5 -> 0 | M5: DIARIA RICARDO | N5: 45626 | O5: 0.5 | P5: 70 | Q5: =O5*P5 -> 35 | R5: R.FERNANDO | T5: 45646 | U5: 2 | V5: 10 | W5: =U5*V5 -> 20
D6: PRIMAZ | E6: 45630 | F6: -10.9 | H6: ACIDO BORICO SACO 25K | I6: =SUMIF(TOMATE!D3:D244,"ACIDO BORICO SACO 25K",TOMATE!F3:F244) -> 5.93 | J6: =COMPRAS!M6 -> 10.2 | K6: =I6*J6 -> 60.486 | M6: DIARIA AMIGO | N6: 45626 | O6: 0.5 | P6: 70 | Q6: =O6*P6 -> 35 | R6: R.FERNANDO | T6: 45652 | U6: 2 | V6: 10 | W6: =U6*V6 -> 20
D7: PLATINUM NEO - GL 5 LITROS | E7: 45636 | F7: 22.5 | H7: ADESIL - 1 LITRO | I7: =SUMIF(TOMATE!D3:D244,"ADESIL - 1 LITRO",TOMATE!F3:F244) -> 0 | J7: =COMPRAS!M7 -> 0.025 | K7: =I7*J7 -> 0 | M7: DIARIA MARKIN | N7: 45633 | O7: 1 | P7: 75 | Q7: =O7*P7 -> 75 | R7: R.FERNANDO | T7: 45657 | U7: 2 | V7: 10 | W7: =U7*V7 -> 20
D8: RIDOMIL GOLD BRAVO 1 LITRO | E8: 45636 | F8: 22.5 | H8: AGRUMAX MZ 4X5 KG | I8: =SUMIF(TOMATE!D3:D244,"AGRUMAX MZ 4X5 KG",TOMATE!F3:F244) -> 0 | J8: =COMPRAS!M8 -> 0.032 | K8: =I8*J8 -> 0 | M8: DIARIA MARKIN | N8: 45633 | O8: 1 | P8: 75 | Q8: =O8*P8 -> 75 | R8: R.FERNANDO | T8: 45660 | U8: 2 | V8: 10 | W8: =U8*V8 -> 20
D9: DRIPSOL INICIAL 15-30-15 25 KG | E9: 45637 | F9: 18.5 | H9: AMISTAR TOP 1 L | I9: =SUMIF(TOMATE!D3:D244,"AMISTAR TOP 1 L",TOMATE!F3:F244) -> 20 | J9: =COMPRAS!M9 -> 0.205 | K9: =I9*J9 -> 4.1 | M9: DIARIA MARKIN | N9: 45633 | O9: 0.5 | P9: 75 | Q9: =O9*P9 -> 37.5 | R9: R.FERNANDO | T9: 45663 | U9: 2 | V9: 10 | W9: =U9*V9 -> 20
D10: DRIPSOL INICIAL 15-30-15 25 KG | E10: 45642 | F10: 18.75 | H10: AMISTAR WG 6X500 G-1 KILO | I10: =SUMIF(TOMATE!D3:D244,"AMISTAR WG 6X500 G-1 KILO",TOMATE!F3:F244) -> 0 | J10: =COMPRAS!M10 -> 0.2 | K10: =I10*J10 -> 0 | M10: DIARIA MARKIN | N10: 45661 | O10: 2 | P10: 75 | Q10: =U8*P10 -> 150 | T10: 45666 | U10: 2 | V10: 10 | W10: =U10*V10 -> 20
D11: FULVUMIM 5 LITROS | E11: 45642 | F11: 1900 | H11: AMPLIGO 250 ML | I11: =SUMIF(TOMATE!D3:D244,"AMPLIGO 250 ML",TOMATE!F3:F244) -> 40 | J11: =COMPRAS!M11 -> 0.39 | K11: =I11*J11 -> 15.6 | M11: DIARIA LUCAS | N11: 45661 | O11: 3 | P11: 80 | Q11: =O11*P11 -> 240 | T11: 45671 | U11: 2 | V11: 10 | W11: =U11*V11 -> 20
D12: RESTORER 5 LITROS | E12: 45642 | F12: 190 | H12: AVATAR 1 L | I12: =SUMIF(TOMATE!D3:D244,"AVATAR 1 L",TOMATE!F3:F244) -> 240 | J12: =COMPRAS!M12 -> 0.375 | K12: =I12*J12 -> 90 | M12: DIDIU | N12: 45663 | O12: 1 | P12: 80 | Q12: =O12*P12 -> 80 | R12: R.JEAN | T12: 45674 | U12: 3 | V12: 10 | W12: =U12*V12 -> 30
D13: ACIDO BORICO SACO 25K | E13: 45642 | F13: 0.75 | H13: BARBANTE EM NOVELO N10 BRANCO | I13: =SUMIF(TOMATE!D3:D244,"BARBANTE EM NOVELO N10 BRANCO",TOMATE!F3:F244) -> 0 | J13: =COMPRAS!M13 -> 29.625 | K13: =I13*J13 -> 0 | M13: DIARIA MARKIN | N13: 45668 | O13: 2 | P13: 75 | Q13: =O13*P13 -> 150 | T13: 45676 | U13: 3 | V13: 10 | W13: =U13*V13 -> 30
D14: RIDOMIL GOLD MZ 680 WG 12X1 1 KG | E14: 45643 | F14: 100 | H14: BARBANTE EM NOVELO N8 OURO | I14: =SUMIF(TOMATE!D3:D244,"BARBANTE EM NOVELO N8 OURO",TOMATE!F3:F244) -> 0 | J14: =COMPRAS!M14 -> 31.576923 | K14: =I14*J14 -> 0 | M14: DIARIA LUCAS | N14: 45668 | O14: 1.5 | P14: 80 | Q14: =O14*P14 -> 120 | T14: 45680 | U14: 3 | V14: 10 | W14: =U14*V14 -> 30
D15: PRIVILEGE 1L | E15: 45643 | F15: 60 | H15: BENZOATO 1K | I15: =SUMIF(TOMATE!D3:D244,"BENZOATO 1K",TOMATE!F3:F244) -> 88 | J15: =COMPRAS!M15 -> 0.45 | K15: =I15*J15 -> 39.6 | M15: DIARIA LUCAS | N15: 45682 | O15: 5.5 | P15: 80 | Q15: =O15*P15 -> 440 | T15: 45681 | U15: 3 | V15: 10 | W15: =U15*V15 -> 30
D16: AMPLIGO 250 ML | E16: 45643 | F16: 40 | H16: BION 500 WG 25 G | I16: =SUMIF(TOMATE!D3:D244,"BION 500 WG 25 G",TOMATE!F3:F244) -> 2 | J16: =COMPRAS!M16 -> 2.8 | K16: =I16*J16 -> 5.6 | M16: DIARIA MARKIN | N16: 45682 | O16: 5 | P16: 75 | Q16: =O16*P16 -> 375 | T16: 45686 | U16: 3 | V16: 10 | W16: =U16*V16 -> 30
D17: FYLLOTON 12X1 1 LITRO | E17: 45646 | F17: 100 | H17: BRAVONIL ULTREX 1 KILO | I17: =SUMIF(TOMATE!D3:D244,"BRAVONIL ULTREX 1 KILO",TOMATE!F3:F244) -> 0 | J17: =COMPRAS!M17 -> 0.1 | K17: =I17*J17 -> 0 | M17: DIARIA LUCAS | N17: 45689 | O17: 4 | P17: 80 | Q17: =O17*P17 -> 320 | R17: R.FERNANDO | T17: 45693 | U17: 3 | V17: 10 | W17: =U17*V17 -> 30
D18: GLIBOR CA 5L | E18: 45646 | F18: 80 | H18: BRIT | I18: =SUMIF(TOMATE!D3:D244,"BRIT",TOMATE!F3:F244) -> 0 | J18: =COMPRAS!M18 -> 0.065 | K18: =I18*J18 -> 0 | M18: DIARIA MARKIN | N18: 45689 | O18: 2 | P18: 75 | Q18: =O18*P18 -> 150 | R18: R.FERNANDO | T18: 45697 | U18: 3 | V18: 10 | W18: =U18*V18 -> 30
D19: N CALCIO CALCINIT YARA 15.5% 18CA 25K | E19: 45650 | F19: 28 | H19: CAIXA PARA TOMATE | I19: =SUMIF(TOMATE!D3:D244,"CAIXA PARA TOMATE ",TOMATE!F3:F244) -> 0 | J19: =COMPRAS!M19 -> 0 | K19: =I19*J19 -> 0 | M19: DIARIA LUCAS | N19: 45696 | O19: 4.5 | P19: 80 | Q19: =O19*P19 -> 360 | R19: R.FERNANDO | T19: 45700 | U19: 3 | V19: 10 | W19: =U19*V19 -> 30
D20: FULVUMIM 5 LITROS | E20: 45650 | F20: 1850 | H20: CAL SUPER 5 LITROS | I20: =SUMIF(TOMATE!D3:D244,"CAL SUPER 5 LITROS",TOMATE!F3:F244) -> 0 | J20: =COMPRAS!M20 -> 0.044 | K20: =I20*J20 -> 0 | M20: FRETE GBI | N20: 45699 | O20: 1 | P20: 15 | Q20: =O20*P20 -> 15 | R20: R.FERNANDO | T20: 45703 | U20: 3 | V20: 10 | W20: =U20*V20 -> 30
D21: RESTORER 5 LITROS | E21: 45650 | F21: 1850 | H21: CARNADINE- 1 LITRO | I21: =SUMIF(TOMATE!D3:D244,"CARNADINE- 1 LITRO",TOMATE!F3:F244) -> 90 | J21: =COMPRAS!M21 -> 0.060833333 | K21: =I21*J21 -> 5.475 | M21: NRITATO DE CALCIO YARA | N21: 45701 | O21: 1 | P21: 85 | Q21: =O21*P21 -> 85 | R21: R.FERNANDO | T21: 45706 | U21: 3 | V21: 10 | W21: =U21*V21 -> 30
D22: DFULL 1 LITRO | E22: 45652 | F22: 80 | H22: CERCOBIN 875 WG- 1 KG | I22: =SUMIF(TOMATE!D3:D244,"CERCOBIN 875 WG- 1 KG",TOMATE!F3:F244) -> 0 | J22: =COMPRAS!M22 -> 0.085 | K22: =I22*J22 -> 0 | M22: DIARIA LUCAS | N22: 45705 | O22: 3 | P22: 80 | Q22: =O22*P22 -> 240 | R22: R.FERNANDO | T22: 45707 | U22: 3 | V22: 10 | W22: =U22*V22 -> 30
D23: D FIX - 1 LITRO | E23: 45652 | F23: 30 | H23: D FIX - 1 LITRO | I23: =SUMIF(TOMATE!D3:D244,"D FIX - 1 LITRO",TOMATE!F3:F244) -> 260 | J23: =COMPRAS!M23 -> 0.11 | K23: =I23*J23 -> 28.6 | M23: DIARIA LUCAS | N23: 45710 | O23: 4 | P23: 80 | Q23: =O23*P23 -> 320 | R23: R.FERNANDO | T23: 45708 | U23: 3 | V23: 10 | W23: =U23*V23 -> 30
D24: D S30 - 1 LITRO | E24: 45652 | F24: 30 | H24: D S30 - 1 LITRO | I24: =SUMIF(TOMATE!D3:D244,"D S30 - 1 LITRO",TOMATE!F3:F244) -> 260 | J24: =COMPRAS!M24 -> 0.065 | K24: =I24*J24 -> 16.9 | T24: 45711 | U24: 4 | V24: 10 | W24: =U24*V24 -> 40
D25: ABADIN 72 EC - 1 LITRO | E25: 45652 | F25: 60 | H25: DELEGATE(TM) - FR 120 GR | I25: =SUMIF(TOMATE!D3:D244,"DELEGATE(TM) - FR 120 GR",TOMATE!F3:F244) -> 20 | J25: =COMPRAS!M25 -> 2.75 | K25: =I25*J25 -> 55 | T25: 45715 | U25: 4 | V25: 10 | W25: =U25*V25 -> 40
D26: MINECTO PRO 12X1LT | E26: 45657 | F26: 40 | H26: DFULL 1 LITRO | I26: =SUMIF(TOMATE!D3:D244,"DFULL 1 LITRO",TOMATE!F3:F244) -> 665 | J26: =COMPRAS!M26 -> 0.155 | K26: =I26*J26 -> 103.075 | T26: 45717 | U26: 3 | V26: 10 | W26: =U26*V26 -> 30
D27: RIDOMIL GOLD MZ 680 WG 12X1 1 KG | E27: 45657 | F27: 60 | H27: DICARZOL 500 SP 12 X 500 GRS | I27: =SUMIF(TOMATE!D3:D244,"DICARZOL 500 SP 12 X 500 GRS",TOMATE!F3:F244) -> 0 | J27: =COMPRAS!M27 -> 0.76 | K27: =I27*J27 -> 0
D28: PIRATE 1 LITRO | E28: 45657 | F28: 60 | H28: DISPAROULTRA-S - GL DE 5 LITROS | I28: =SUMIF(TOMATE!D3:D244,"DISPAROULTRA-S - GL DE 5 LITROS",TOMATE!F3:F244) -> 0 | J28: =COMPRAS!M28 -> 0.028 | K28: =I28*J28 -> 0
D29: DRIPSOL MULTIPROPOSITO-18-18-18 25 K | E29: 45690 | F29: 37 | H29: DOMINUM XT-S - GL 5 LITROS | I29: =SUMIF(TOMATE!D3:D244,"DOMINUM XT-S - GL 5 LITROS",TOMATE!F3:F244) -> 0 | J29: =COMPRAS!M29 -> 0.128 | K29: =I29*J29 -> 0
D30: DFULL 1 LITRO | E30: 45660 | F30: 80 | H30: DRIPSOL BORO K 00.00.01+17% BORO 25 k | I30: =SUMIF(TOMATE!D3:D244,"DRIPSOL BORO K 00.00.01+17% BORO 25 k",TOMATE!F3:F244) -> 0 | J30: =COMPRAS!M30 -> 11.4 | K30: =I30*J30 -> 0
D31: D FIX - 1 LITRO | E31: 45660 | F31: 30 | H31: DRIPSOL CRESCIMENTO 24-10-10 25 KG | I31: =SUMIF(TOMATE!D3:D244,"DRIPSOL CRESCIMENTO 24-10-10 25 KG",TOMATE!F3:F244) -> 0 | J31: =COMPRAS!M31 -> 10.6 | K31: =I31*J31 -> 0
D32: D S30 - 1 LITRO | E32: 45660 | F32: 30 | H32: DRIPSOL INICIAL 15-30-15 25 KG | I32: =SUMIF(TOMATE!D3:D244,"DRIPSOL INICIAL 15-30-15 25 KG",TOMATE!F3:F244) -> 37.25 | J32: =COMPRAS!M32 -> 9.2769231 | K32: =I32*J32 -> 345.56538
D33: ABADIN 72 EC - 1 LITRO | E33: 45660 | F33: 60 | H33: DRIPSOL MICRO REXENE 700 GRAMAS | I33: =SUMIF(TOMATE!D3:D244,"DRIPSOL MICRO REXENE 700 GRAMAS",TOMATE!F3:F244) -> 0 | J33: =COMPRAS!M33 -> 0.082857143 | K33: =I33*J33 -> 0
D34: SULFATO DE MAGNESIO-KRISTA MGS 25K | E34: 45661 | F34: 15 | H34: DRIPSOL MULTIPROPOSITO-18-18-18 25 K | I34: =SUMIF(TOMATE!D3:D244,"DRIPSOL MULTIPROPOSITO-18-18-18 25 K",TOMATE!F3:F244) -> 79 | J34: =COMPRAS!M34 -> 10.56 | K34: =I34*J34 -> 834.24
D35: N CALCIO CALCINIT YARA 15.5% 18CA 25K | E35: 45663 | F35: 25 | H35: DRIPSOL PRODUÇÃO 12-06-40 25K | I35: =SUMIF(TOMATE!D3:D244,"DRIPSOL PRODUÇÃO 12-06-40 25K",TOMATE!F3:F244) -> 0 | J35: =COMPRAS!M35 -> 11 | K35: =I35*J35 -> 0 | N35: TOTAL | O35: =SUM(O3:O34) -> 44 | Q35: =SUM(Q3:Q34) -> 3372.5 | T35: TOTAL | U35: =SUM(U3:U31) -> 64.5 | W35: =SUM(W3:W31) -> 645
D36: FULVUMIM 5 LITROS | E36: 45663 | F36: 1900 | H36: ELEITTO | I36: =SUMIF(TOMATE!D3:D244,"ELEITTO",TOMATE!F3:F244) -> 0 | J36: =COMPRAS!M36 -> 0.33 | K36: =I36*J36 -> 0
D37: RESTORER 5 LITROS | E37: 45663 | F37: 1900 | H37: FERTIUM LIQUIDO 5L | I37: =SUMIF(TOMATE!D3:D244,"FERTIUM LIQUIDO 5L",TOMATE!F3:F244) -> 0 | J37: =COMPRAS!M37 -> 0.217 | K37: =I37*J37 -> 0
D38: MICROCOMPLEX 1X25 25K | E38: 45663 | F38: 0.95 | H38: FITILHO VIRGEM NOVELO NR 08 | I38: =SUMIF(TOMATE!D3:D244,"FITILHO VIRGEM NOVELO NR 08",TOMATE!F3:F244) -> 0 | J38: =COMPRAS!M38 -> 40 | K38: =I38*J38 -> 0 | M38: REEMBOLSO DE PAGAMENTO | S38: REEMBOLSO DE PAGAMENTO
D39: FULVUMIM 5 LITROS | E39: 45663 | F39: 100 | H39: FRETE CAIXAS TOMATE | I39: =SUMIF(TOMATE!D3:D244,"FRETE CAIXAS TOMATE ",TOMATE!F3:F244) -> 0 | J39: =COMPRAS!M39 -> 2.3571429 | K39: =I39*J39 -> 0 | M39: REEMBOLSO FERNANDO | N39: =SUMIF(TOMATE!R1:R30,"R.FERNANDO",TOMATE!Q1:Q30) -> 1817.5 | S39: REEMBOLSO FERNANDO | T39: =SUMIF(TOMATE!X1:X30,"R.FERNANDO",TOMATE!W1:W30) -> 0
D40: NUTRIGEMMA B ZN 5 LITROS | E40: 45663 | F40: 80 | H40: FTE 25K | I40: =SUMIF(TOMATE!D3:D244,"FTE 25K",TOMATE!F3:F244) -> 0 | J40: =COMPRAS!M40 -> 4.4 | K40: =I40*J40 -> 0 | M40: REEMBOLSO RAFAEL | N40: =SUMIF(TOMATE!R1:R30,"R.RAFAEL",TOMATE!Q1:Q30) -> 0 | S40: REEMBOLSO RAFAEL | T40: =SUMIF(TOMATE!X1:X30,"R.RAFAEL",TOMATE!W1:W30) -> 0
...

Sheet COMPRAS
A1: COMPRAS CONFINAMENTO | J1: EQUIPARAÇÃO DE PREÇOS
A2: DESCRIÇÃO | B2: DATA | C2: QUANT | D2: UNIDADE | E2: TOTAL | F2: VALOR | G2: FORNECEDOR/N DE NOTA | H2: COMPRADO POR | J2: DESCRIÇÃO | K2: COMPRA TOTAL | L2: VALOR TOTAL | M2: PREÇO EQUIPARADO
A3: ADESIL - 1 LITRO | B3: 45299 | C3: 1 | D3: 1000 | E3: =C3*D3 -> 1000 | F3: 25 | G3: UNIAGRO NOTA 58496 | J3: ABADIN 72 EC - 1 LITRO | K3: =SUMIF(COMPRAS!A3:A183,"ABADIN 72 EC - 1 LITRO",COMPRAS!E3:E183) -> 2000 | L3: =SUMIF(COMPRAS!A3:A183,"ABADIN 72 EC - 1 LITRO",COMPRAS!F3:F183) -> 260 | M3: =L3/K3 -> 0.13
A4: PLATINUM NEO - GL 5 LITROS | B4: 45299 | C4: 1 | D4: 5000 | E4: =C4*D4 -> 5000 | F4: 1000 | G4: UNIAGRO NOTA 58496 | J4: ABAMEX -1 LITRO | K4: =SUMIF(COMPRAS!A3:A183,"ABAMEX -1 LITRO",COMPRAS!E3:E183) -> 1000 | L4: =SUMIF(COMPRAS!A3:A183,"ABAMEX -1 LITRO",COMPRAS!F3:F183) -> 50 | M4: =L4/K4 -> 0.05
A5: QUIMIFOL P30W- GL 5 LITROS | B5: 45299 | C5: 1 | D5: 5000 | E5: =C5*D5 -> 5000 | F5: 180 | G5: UNIAGRO NOTA 58496 | J5: ABAMEX MAXX 72% 12X1 LT | K5: =SUMIF(COMPRAS!A3:A183,"ABAMEX MAXX 72% 12X1 LT",COMPRAS!E3:E183) -> 1000 | L5: =SUMIF(COMPRAS!A3:A183,"ABAMEX MAXX 72% 12X1 LT",COMPRAS!F3:F183) -> 100 | M5: =L5/K5 -> 0.1
A6: QUIMIFOL PHFOS - 1 LITRO | B6: 45299 | C6: 1 | D6: 1000 | E6: =C6*D6 -> 1000 | F6: 60 | G6: UNIAGRO NOTA 58496 | J6: ACIDO BORICO SACO 25K | K6: =SUMIF(COMPRAS!A3:A183,"ACIDO BORICO SACO 25K",COMPRAS!E3:E183) -> 25 | L6: =SUMIF(COMPRAS!A3:A183,"ACIDO BORICO SACO 25K",COMPRAS!F3:F183) -> 255 | M6: =L6/K6 -> 10.2
A7: ROUNDUP ORIGINAL MAIS - GL DE 5 L | B7: 45299 | C7: 1 | D7: 5000 | E7: =C7*D7 -> 5000 | F7: 195 | G7: UNIAGRO NOTA 58496 | J7: ADESIL - 1 LITRO | K7: =SUMIF(COMPRAS!A3:A183,"ADESIL - 1 LITRO",COMPRAS!E3:E183) -> 1000 | L7: =SUMIF(COMPRAS!A3:A183,"ADESIL - 1 LITRO",COMPRAS!F3:F183) -> 25 | M7: =L7/K7 -> 0.025
A8: ABADIN 72 EC - 1 LITRO | B8: 45309 | C8: 2 | D8: 1000 | E8: =C8*D8 -> 2000 | F8: 260 | G8: UNIAGRO NOTA 59051 | J8: AGRUMAX MZ 4X5 KG | K8: =SUMIF(COMPRAS!A3:A183,"AGRUMAX MZ 4X5 KG",COMPRAS!E3:E183) -> 5000 | L8: =SUMIF(COMPRAS!A3:A183,"AGRUMAX MZ 4X5 KG",COMPRAS!F3:F183) -> 160 | M8: =L8/K8 -> 0.032
A9: ABAMEX -1 LITRO | B9: 45309 | C9: 1 | D9: 1000 | E9: =C9*D9 -> 1000 | F9: 50 | G9: UNIAGRO NOTA 59051 | J9: AMISTAR TOP 1 L | K9: =SUMIF(COMPRAS!A3:A183,"AMISTAR TOP 1 L",COMPRAS!E3:E183) -> 1000 | L9: =SUMIF(COMPRAS!A3:A183,"AMISTAR TOP 1 L",COMPRAS!F3:F183) -> 205 | M9: =L9/K9 -> 0.205
A10: KLORPAN 480 CE -1 LITRO | B10: 45309 | C10: 10 | D10: 1000 | E10: =C10*D10 -> 10000 | F10: 380 | G10: UNIAGRO NOTA 59051 | J10: AMISTAR WG 6X500 G-1 KILO | K10: =SUMIF(COMPRAS!A3:A183,"AMISTAR WG 6X500 G-1 KILO",COMPRAS!E3:E183) -> 1000 | L10: =SUMIF(COMPRAS!A3:A183,"AMISTAR WG 6X500 G-1 KILO",COMPRAS!F3:F183) -> 200 | M10: =L10/K10 -> 0.2
A11: QUIMIFOL IMPACTO - 1 LITRO | B11: 45309 | C11: 1 | D11: 1000 | E11: =C11*D11 -> 1000 | F11: 220 | G11: UNIAGRO NOTA 59051 | J11: AMPLIGO 250 ML | K11: =SUMIF(COMPRAS!A3:A183,"AMPLIGO 250 ML",COMPRAS!E3:E183) -> 1000 | L11: =SUMIF(COMPRAS!A3:A183,"AMPLIGO 250 ML",COMPRAS!F3:F183) -> 390 | M11: =L11/K11 -> 0.39
A12: SEMENTE MELANCIA CRIMSON SELE | B12: 45309 | C12: 1 | D12: 1000 | E12: =C12*D12 -> 1000 | F12: 290 | G12: UNIAGRO NOTA 59051 | J12: AVATAR 1 L | K12: =SUMIF(COMPRAS!A3:A183,"AVATAR 1 L",COMPRAS!E3:E183) -> 2000 | L12: =SUMIF(COMPRAS!A3:A183,"AVATAR 1 L",COMPRAS!F3:F183) -> 750 | M12: =L12/K12 -> 0.375
A13: DICARZOL 500 SP 12 X 500 GRS | B13: 45321 | C13: 1 | D13: 500 | E13: =C13*D13 -> 500 | F13: 380 | G13: UNIAGRO NOTA 59471 | J13: BARBANTE EM NOVELO N10 BRANCO | K13: =SUMIF(COMPRAS!A3:A183,"BARBANTE EM NOVELO N10 BRANCO",COMPRAS!E3:E183) -> 40 | L13: =SUMIF(COMPRAS!A3:A183,"BARBANTE EM NOVELO N10 BRANCO",COMPRAS!F3:F183) -> 1185 | M13: =L13/K13 -> 29.625
A14: QUIMIFOL S450 - GL 5 LITROS | B14: 45321 | C14: 1 | D14: 5000 | E14: =C14*D14 -> 5000 | F14: 210 | G14: UNIAGRO NOTA 59471 | J14: BARBANTE EM NOVELO N8 OURO | K14: =SUMIF(COMPRAS!A3:A183,"BARBANTE EM NOVELO N8 OURO",COMPRAS!E3:E183) -> 26 | L14: =SUMIF(COMPRAS!A3:A183,"BARBANTE EM NOVELO N8 OURO",COMPRAS!F3:F183) -> 821 | M14: =L14/K14 -> 31.576923
A15: RAPEL PCT- 3 KG | B15: 45321 | C15: 1 | D15: 3000 | E15: =C15*D15 -> 3000 | F15: 170 | G15: UNIAGRO NOTA 59471 | J15: BENZOATO 1K | K15: =SUMIF(COMPRAS!A3:A183,"BENZOATO 1K",COMPRAS!E3:E183) -> 1000 | L15: =SUMIF(COMPRAS!A3:A183,"BENZOATO 1K",COMPRAS!F3:F183) -> 450 | M15: =L15/K15 -> 0.45
A16: ROUNDUP ORIGINAL MAIS - GL DE 5 L | B16: 45321 | C16: 1 | D16: 5000 | E16: =C16*D16 -> 5000 | F16: 220 | G16: UNIAGRO NOTA 59471 | J16: BION 500 WG 25 G | K16: =SUMIF(COMPRAS!A3:A183,"BION 500 WG 25 G",COMPRAS!E3:E183) -> 75 | L16: =SUMIF(COMPRAS!A3:A183,"BION 500 WG 25 G",COMPRAS!F3:F183) -> 210 | M16: =L16/K16 -> 2.8
A17: KLORPAN 480 CE -1 LITRO | B17: 45328 | C17: 1 | D17: 1000 | E17: =C17*D17 -> 1000 | F17: 50 | G17: UNIAGRO NOTA 59729 | J17: BRAVONIL ULTREX 1 KILO | K17: =SUMIF(COMPRAS!A3:A183,"BRAVONIL ULTREX 1 KILO",COMPRAS!E3:E183) -> 1000 | L17: =SUMIF(COMPRAS!A3:A183,"BRAVONIL ULTREX 1 KILO",COMPRAS!F3:F183) -> 100 | M17: =L17/K17 -> 0.1
A18: RAPEL PCT- 3 KG | B18: 45328 | C18: 1 | D18: 3000 | E18: =C18*D18 -> 3000 | F18: 170 | G18: UNIAGRO NOTA 59729 | J18: BRIT | K18: =SUMIF(COMPRAS!A3:A183,"BRIT ",COMPRAS!E3:E183) -> 1000 | L18: =SUMIF(COMPRAS!A3:A183,"BRIT ",COMPRAS!F3:F183) -> 65 | M18: =L18/K18 -> 0.065
A19: CARNADINE- 1 LITRO | B19: 45329 | C19: 1 | D19: 1000 | E19: =C19*D19 -> 1000 | F19: 65 | G19: UNIAGRO NOTA 59811 | J19: CAIXA PARA TOMATE
A20: CERCOBIN 875 WG- 1 KG | B20: 45329 | C20: 1 | D20: 1000 | E20: =C20*D20 -> 1000 | F20: 85 | G20: UNIAGRO NOTA 59811 | J20: CAL SUPER 5 LITROS | K20: =SUMIF(COMPRAS!A3:A183,"CAL SUPER 5 LITROS",COMPRAS!E3:E183) -> 5000 | L20: =SUMIF(COMPRAS!A3:A183,"CAL SUPER 5 LITROS",COMPRAS!F3:F183) -> 220 | M20: =L20/K20 -> 0.044
A21: QUIMIFOL CALCIO E BORO II- BD 20 L | B21: 45329 | C21: 1 | D21: 20000 | E21: =C21*D21 -> 20000 | F21: 470 | G21: UNIAGRO NOTA 59811 | J21: CARNADINE- 1 LITRO | K21: =SUMIF(COMPRAS!A3:A183,"CARNADINE- 1 LITRO",COMPRAS!E3:E183) -> 6000 | L21: =SUMIF(COMPRAS!A3:A183,"CARNADINE- 1 LITRO",COMPRAS!F3:F183) -> 365 | M21: =L21/K21 -> 0.060833333
A22: SCORE 250 EC - 1 LITRO | B22: 45329 | C22: 1 | D22: 1000 | E22: =C22*D22 -> 1000 | F22: 95 | G22: UNIAGRO NOTA 59811 | J22: CERCOBIN 875 WG- 1 KG | K22: =SUMIF(COMPRAS!A3:A183,"CERCOBIN 875 WG- 1 KG",COMPRAS!E3:E183) -> 1000 | L22: =SUMIF(COMPRAS!A3:A183,"CERCOBIN 875 WG- 1 KG",COMPRAS!F3:F183) -> 85 | M22: =L22/K22 -> 0.085
A23: CARNADINE- 1 LITRO | B23: 45341 | C23: 1 | D23: 5000 | E23: =C23*D23 -> 5000 | F23: 300 | G23: UNIAGRO NOTA 60135 | J23: D FIX - 1 LITRO | K23: =SUMIF(COMPRAS!A3:A183,"D FIX - 1 LITRO",COMPRAS!E3:E183) -> 1000 | L23: =SUMIF(COMPRAS!A3:A183,"D FIX - 1 LITRO",COMPRAS!F3:F183) -> 110 | M23: =L23/K23 -> 0.11
A24: PROGIBB 400 - PCT 2,5 GR | B24: 45440 | C24: 16 | D24: 2.5 | E24: =C24*D24 -> 40 | F24: 240 | G24: UNIAGRO NOTA 61385 | J24: D S30 - 1 LITRO | K24: =SUMIF(COMPRAS!A3:A183,"D S30 - 1 LITRO",COMPRAS!E3:E183) -> 1000 | L24: =SUMIF(COMPRAS!A3:A183,"D S30 - 1 LITRO",COMPRAS!F3:F183) -> 65 | M24: =L24/K24 -> 0.065
A25: AMISTAR WG 6X500 G-1 KILO | B25: 45498 | C25: 1 | D25: 1000 | E25: =C25*D25 -> 1000 | F25: 200 | G25: TABELA ANTIGA DO TOMATE COMPRAS RAMON | J25: DELEGATE(TM) - FR 120 GR | K25: =SUMIF(COMPRAS!A3:A183,"DELEGATE(TM) - FR 120 GR",COMPRAS!E3:E183) -> 480 | L25: =SUMIF(COMPRAS!A3:A183,"DELEGATE(TM) - FR 120 GR",COMPRAS!F3:F183) -> 1320 | M25: =L25/K25 -> 2.75
A26: TOPMIX 03-28-00 YARA 50K | B26: 45509 | C26: 13 | D26: 25 | E26: =C26*D26 -> 325 | F26: 2210 | G26: HF NOTA 43526 | H26: CONFINAMENTO/FERNANDO | J26: DFULL 1 LITRO | K26: =SUMIF(COMPRAS!A3:A183,"DFULL 1 LITRO",COMPRAS!E3:E183) -> 2000 | L26: =SUMIF(COMPRAS!A3:A183,"DFULL 1 LITRO",COMPRAS!F3:F183) -> 310 | M26: =L26/K26 -> 0.155
A27: QUIMIFOL TQ CLEAR - 1 LITRO | B27: 45512 | C27: 1 | D27: 1000 | E27: =C27*D27 -> 1000 | F27: 95 | G27: UNIAGRO NOTA 61956 | J27: DICARZOL 500 SP 12 X 500 GRS | K27: =SUMIF(COMPRAS!A3:A183,"DICARZOL 500 SP 12 X 500 GRS",COMPRAS!E3:E183) -> 500 | L27: =SUMIF(COMPRAS!A3:A183,"DICARZOL 500 SP 12 X 500 GRS",COMPRAS!F3:F183) -> 380 | M27: =L27/K27 -> 0.76
A28: DRIPSOL INICIAL 15-30-15 25 KG | B28: 45520 | C28: 10 | D28: 25 | E28: =C28*D28 -> 250 | F28: 2260 | G28: HF NOTA 43697 | H28: CONFINAMENTO/RAFAEL | J28: DISPAROULTRA-S - GL DE 5 LITROS | K28: =SUMIF(COMPRAS!A3:A183,"DISPAROULTRA-S - GL DE 5 LITROS",COMPRAS!E3:E183) -> 5000 | L28: =SUMIF(COMPRAS!A3:A183,"DISPAROULTRA-S - GL DE 5 LITROS",COMPRAS!F3:F183) -> 140 | M28: =L28/K28 -> 0.028
A29: FULVUMIM 5 LITROS | B29: 45520 | C29: 4 | D29: 5000 | E29: =C29*D29 -> 20000 | F29: 660 | G29: HF NOTA 43697 | H29: CONFINAMENTO/RAFAEL | J29: DOMINUM XT-S - GL 5 LITROS | K29: =SUMIF(COMPRAS!A3:A183,"DOMINUM XT-S - GL 5 LITROS",COMPRAS!E3:E183) -> 10000 | L29: =SUMIF(COMPRAS!A3:A183,"DOMINUM XT-S - GL 5 LITROS",COMPRAS!F3:F183) -> 1280 | M29: =L29/K29 -> 0.128
A30: RESTORER 5 LITROS | B30: 45520 | C30: 3 | D30: 5000 | E30: =C30*D30 -> 15000 | F30: 480 | G30: HF NOTA 43697 | H30: CONFINAMENTO/RAFAEL | J30: DRIPSOL BORO K 00.00.01+17% BORO 25 k | K30: =SUMIF(COMPRAS!A3:A183,"DRIPSOL BORO K 00.00.01+17% BORO 25 k",COMPRAS!E3:E183) -> 25 | L30: =SUMIF(COMPRAS!A3:A183,"DRIPSOL BORO K 00.00.01+17% BORO 25 k",COMPRAS!F3:F183) -> 285 | M30: =L30/K30 -> 11.4
A31: BION 500 WG 25 G | B31: 45524 | C31: 3 | D31: 25 | E31: =C31*D31 -> 75 | F31: 210 | G31: HF NOTA 43754 | H31: CONFINAMENTO/RAFAEL | J31: DRIPSOL CRESCIMENTO 24-10-10 25 KG | K31: =SUMIF(COMPRAS!A3:A183,"DRIPSOL CRESCIMENTO 24-10-10 25 KG",COMPRAS!E3:E183) -> 25 | L31: =SUMIF(COMPRAS!A3:A183,"DRIPSOL CRESCIMENTO 24-10-10 25 KG",COMPRAS!F3:F183) -> 265 | M31: =L31/K31 -> 10.6
A32: DRIPSOL MICRO REXENE 700 GRAMAS | B32: 45524 | C32: 2 | D32: 700 | E32: =C32*D32 -> 1400 | F32: 116 | G32: HF NOTA 43754 | H32: CONFINAMENTO/RAFAEL | J32: DRIPSOL INICIAL 15-30-15 25 KG | K32: =SUMIF(COMPRAS!A3:A183,"DRIPSOL INICIAL 15-30-15 25 KG",COMPRAS!E3:E183) -> 325 | L32: =SUMIF(COMPRAS!A3:A183,"DRIPSOL INICIAL 15-30-15 25 KG",COMPRAS!F3:F183) -> 3015 | M32: =L32/K32 -> 9.2769231
A33: DRIPSOL MULTIPROPOSITO-18-18-18 25 K | B33: 45524 | C33: 5 | D33: 25 | E33: =C33*D33 -> 125 | F33: 1325 | G33: HF NOTA 43754 | H33: CONFINAMENTO/RAFAEL | J33: DRIPSOL MICRO REXENE 700 GRAMAS | K33: =SUMIF(COMPRAS!A3:A183,"DRIPSOL MICRO REXENE 700 GRAMAS",COMPRAS!E3:E183) -> 1400 | L33: =SUMIF(COMPRAS!A3:A183,"DRIPSOL MICRO REXENE 700 GRAMAS",COMPRAS!F3:F183) -> 116 | M33: =L33/K33 -> 0.082857143
A34: FYLLOTON 12X1 1 LITRO | B34: 45524 | C34: 3 | D34: 1000 | E34: =C34*D34 -> 3000 | F34: 210 | G34: HF NOTA 43754 | H34: CONFINAMENTO/RAFAEL | J34: DRIPSOL MULTIPROPOSITO-18-18-18 25 K | K34: =SUMIF(COMPRAS!A3:A183,"DRIPSOL MULTIPROPOSITO-18-18-18 25 K",COMPRAS!E3:E183) -> 550 | L34: =SUMIF(COMPRAS!A3:A183,"DRIPSOL MULTIPROPOSITO-18-18-18 25 K",COMPRAS!F3:F183) -> 5808 | M34: =L34/K34 -> 10.56
A35: N CALCIO CALCINIT YARA 15.5% 18CA 25K | B35: 45524 | C35: 3 | D35: 25 | E35: =C35*D35 -> 75 | F35: 270 | G35: HF NOTA 43754 | H35: CONFINAMENTO/RAFAEL | J35: DRIPSOL PRODUÇÃO 12-06-40 25K | K35: =SUMIF(COMPRAS!A3:A183,"DRIPSOL PRODUÇÃO 12-06-40 25K",COMPRAS!E3:E183) -> 25 | L35: =SUMIF(COMPRAS!A3:A183,"DRIPSOL PRODUÇÃO 12-06-40 25K",COMPRAS!F3:F183) -> 275 | M35: =L35/K35 -> 11
A36: POQUER 4X5 LITROS | B36: 45524 | C36: 1 | D36: 5000 | E36: =C36*D36 -> 5000 | F36: 163 | G36: HF NOTA 43754 | H36: CONFINAMENTO/RAFAEL | J36: ELEITTO | K36: =SUMIF(COMPRAS!A3:A183,"ELEITTO",COMPRAS!E3:E183) -> 1000 | L36: =SUMIF(COMPRAS!A3:A183,"ELEITTO",COMPRAS!F3:F183) -> 330 | M36: =L36/K36 -> 0.33
A37: PROTAMIN 25K | B37: 45524 | C37: 3 | D37: 25 | E37: =C37*D37 -> 75 | F37: 360 | G37: HF NOTA 43754 | H37: CONFINAMENTO/RAFAEL | J37: FERTIUM LIQUIDO 5L | K37: =SUMIF(COMPRAS!A3:A183,"FERTIUM LIQUIDO 5L",COMPRAS!E3:E183) -> 1000 | L37: =SUMIF(COMPRAS!A3:A183,"FERTIUM LIQUIDO 5L",COMPRAS!F3:F183) -> 217 | M37: =L37/K37 -> 0.217
A38: SULFATO DE MAGNESIO-KRISTA MGS 25K | B38: 45524 | C38: 3 | D38: 25 | E38: =C38*D38 -> 75 | F38: 234 | G38: HF NOTA 43754 | H38: CONFINAMENTO/RAFAEL | J38: FITILHO VIRGEM NOVELO NR 08 | K38: =SUMIF(COMPRAS!A3:A183,"FITILHO VIRGEM NOVELO NR 08",COMPRAS!E3:E183) -> 2 | L38: =SUMIF(COMPRAS!A4:A184,"FITILHO VIRGEM NOVELO NR 08",COMPRAS!F4:F184) -> 80 | M38: =L38/K38 -> 40
A39: TOPMIX 03-28-00 YARA 50K | B39: 45524 | C39: 6 | D39: 25 | E39: =C39*D39 -> 150 | F39: 1020 | G39: HF NOTA 43754 | H39: CONFINAMENTO/RAFAEL | J39: FRETE CAIXAS TOMATE | K39: =SUMIF(COMPRAS!A3:A183,"FRETE CAIXAS TOMATE",COMPRAS!E3:E183) -> 350 | L39: =SUMIF(COMPRAS!A3:A183,"FRETE CAIXAS TOMATE",COMPRAS!F3:F183) -> 825 | M39: =L39/K39 -> 2.3571429
A40: SEMENTE DE MILHO BIOMATRIX 3066 | B40: 45527 | C40: 4 | D40: 2 | E40: =C40*D40 -> 8 | F40: 540 | G40: TABELA CONFINAMENTO FINANCEIRO | J40: FTE 25K | K40: =SUMIF(COMPRAS!A3:A183,"FTE 25K",COMPRAS!E3:E183) -> 25 | L40: =SUMIF(COMPRAS!A3:A183,"FTE 25K",COMPRAS!F3:F183) -> 110 | M40: =L40/K40 -> 4.4
...

Sheet FECHAMENTOS
A1: CONFINAMENTO-MILHO | D1: CONFINAMENTO-TOMATE
A2: DESCRIÇÃO | B2: VALOR | D2: DESCRIÇÃO | E2: VALOR
A3: IRRIGAÇÃO | B3: ='CONFINAMENTO-MILHO'!B106 -> 1583.88 | D3: IRRIGAÇÃO | E3: =TOMATE!B106 -> 0
A4: ADUBOS | B4: ='CONFINAMENTO-MILHO'!K120 -> 2126.948 | D4: ADUBOS | E4: =TOMATE!K120 -> 7424.0025
A5: DIARIAS DE TRABALHADOR | B5: ='CONFINAMENTO-MILHO'!Q35 -> 4103.2 | D5: DIARIAS DE TRABALHADOR | E5: =TOMATE!Q35 -> 3372.5
A6: MAQUINA DE VENENO | B6: ='CONFINAMENTO-MILHO'!W35 -> 240 | D6: MAQUINA DE VENENO | E6: =TOMATE!W35 -> 645
A11: TOTAL | B11: =SUM(B3:B10) -> 8054.028 | D11: TOTAL | E11: =SUM(E3:E10) -> 11441.503
